[2025-04-29T00:03:24.595+0000] {taskinstance.py:1165} INFO - Dependencies all met for <TaskInstance: user_processing.is_api_available scheduled__2025-04-28T00:00:00+00:00 [queued]>
[2025-04-29T00:03:24.651+0000] {taskinstance.py:1165} INFO - Dependencies all met for <TaskInstance: user_processing.is_api_available scheduled__2025-04-28T00:00:00+00:00 [queued]>
[2025-04-29T00:03:24.654+0000] {taskinstance.py:1362} INFO - 
--------------------------------------------------------------------------------
[2025-04-29T00:03:24.656+0000] {taskinstance.py:1363} INFO - Starting attempt 1 of 1
[2025-04-29T00:03:24.657+0000] {taskinstance.py:1364} INFO - 
--------------------------------------------------------------------------------
[2025-04-29T00:03:24.728+0000] {taskinstance.py:1383} INFO - Executing <Task(HttpSensor): is_api_available> on 2025-04-28 00:00:00+00:00
[2025-04-29T00:03:24.767+0000] {standard_task_runner.py:55} INFO - Started process 4359 to run task
[2025-04-29T00:03:24.784+0000] {standard_task_runner.py:82} INFO - Running: ['***', 'tasks', 'run', 'user_processing', 'is_api_available', 'scheduled__2025-04-28T00:00:00+00:00', '--job-id', '286', '--raw', '--subdir', 'DAGS_FOLDER/user_processing.py', '--cfg-path', '/tmp/tmp_43anzpx']
[2025-04-29T00:03:24.794+0000] {standard_task_runner.py:83} INFO - Job 286: Subtask is_api_available
[2025-04-29T00:03:25.109+0000] {task_command.py:376} INFO - Running <TaskInstance: user_processing.is_api_available scheduled__2025-04-28T00:00:00+00:00 [running]> on host fae2b1eff5d6
[2025-04-29T00:03:25.392+0000] {taskinstance.py:1592} INFO - Exporting the following env vars:
AIRFLOW_CTX_DAG_OWNER=***
AIRFLOW_CTX_DAG_ID=user_processing
AIRFLOW_CTX_TASK_ID=is_api_available
AIRFLOW_CTX_EXECUTION_DATE=2025-04-28T00:00:00+00:00
AIRFLOW_CTX_TRY_NUMBER=1
AIRFLOW_CTX_DAG_RUN_ID=scheduled__2025-04-28T00:00:00+00:00
[2025-04-29T00:03:25.406+0000] {http.py:120} INFO - Poking: api/
[2025-04-29T00:03:25.440+0000] {base.py:71} INFO - Using connection ID 'user_api' for task execution.
[2025-04-29T00:03:25.481+0000] {http.py:148} INFO - Sending 'GET' to url: https://randomuser.me/api/
[2025-04-29T01:14:15.488+0000] {http.py:206} WARNING - ('Connection aborted.', RemoteDisconnected('Remote end closed connection without response')) Tenacity will retry to execute the operation
[2025-04-29T01:14:15.500+0000] {taskinstance.py:1851} ERROR - Task failed with exception
Traceback (most recent call last):
  File "/home/airflow/.local/lib/python3.7/site-packages/urllib3/connectionpool.py", line 710, in urlopen
    chunked=chunked,
  File "/home/airflow/.local/lib/python3.7/site-packages/urllib3/connectionpool.py", line 449, in _make_request
    six.raise_from(e, None)
  File "<string>", line 3, in raise_from
  File "/home/airflow/.local/lib/python3.7/site-packages/urllib3/connectionpool.py", line 444, in _make_request
    httplib_response = conn.getresponse()
  File "/usr/local/lib/python3.7/http/client.py", line 1373, in getresponse
    response.begin()
  File "/usr/local/lib/python3.7/http/client.py", line 319, in begin
    version, status, reason = self._read_status()
  File "/usr/local/lib/python3.7/http/client.py", line 288, in _read_status
    raise RemoteDisconnected("Remote end closed connection without"
http.client.RemoteDisconnected: Remote end closed connection without response

During handling of the above exception, another exception occurred:

Traceback (most recent call last):
  File "/home/airflow/.local/lib/python3.7/site-packages/requests/adapters.py", line 499, in send
    timeout=timeout,
  File "/home/airflow/.local/lib/python3.7/site-packages/urllib3/connectionpool.py", line 788, in urlopen
    method, url, error=e, _pool=self, _stacktrace=sys.exc_info()[2]
  File "/home/airflow/.local/lib/python3.7/site-packages/urllib3/util/retry.py", line 550, in increment
    raise six.reraise(type(error), error, _stacktrace)
  File "/home/airflow/.local/lib/python3.7/site-packages/urllib3/packages/six.py", line 769, in reraise
    raise value.with_traceback(tb)
  File "/home/airflow/.local/lib/python3.7/site-packages/urllib3/connectionpool.py", line 710, in urlopen
    chunked=chunked,
  File "/home/airflow/.local/lib/python3.7/site-packages/urllib3/connectionpool.py", line 449, in _make_request
    six.raise_from(e, None)
  File "<string>", line 3, in raise_from
  File "/home/airflow/.local/lib/python3.7/site-packages/urllib3/connectionpool.py", line 444, in _make_request
    httplib_response = conn.getresponse()
  File "/usr/local/lib/python3.7/http/client.py", line 1373, in getresponse
    response.begin()
  File "/usr/local/lib/python3.7/http/client.py", line 319, in begin
    version, status, reason = self._read_status()
  File "/usr/local/lib/python3.7/http/client.py", line 288, in _read_status
    raise RemoteDisconnected("Remote end closed connection without"
urllib3.exceptions.ProtocolError: ('Connection aborted.', RemoteDisconnected('Remote end closed connection without response'))

During handling of the above exception, another exception occurred:

Traceback (most recent call last):
  File "/home/airflow/.local/lib/python3.7/site-packages/airflow/sensors/base.py", line 189, in execute
    poke_return = self.poke(context)
  File "/home/airflow/.local/lib/python3.7/site-packages/airflow/providers/http/sensors/http.py", line 126, in poke
    extra_options=self.extra_options,
  File "/home/airflow/.local/lib/python3.7/site-packages/airflow/providers/http/hooks/http.py", line 149, in run
    return self.run_and_check(session, prepped_request, extra_options)
  File "/home/airflow/.local/lib/python3.7/site-packages/airflow/providers/http/hooks/http.py", line 207, in run_and_check
    raise ex
  File "/home/airflow/.local/lib/python3.7/site-packages/airflow/providers/http/hooks/http.py", line 199, in run_and_check
    response = session.send(prepped_request, **send_kwargs)
  File "/home/airflow/.local/lib/python3.7/site-packages/requests/sessions.py", line 701, in send
    r = adapter.send(request, **kwargs)
  File "/home/airflow/.local/lib/python3.7/site-packages/requests/adapters.py", line 547, in send
    raise ConnectionError(err, request=request)
requests.exceptions.ConnectionError: ('Connection aborted.', RemoteDisconnected('Remote end closed connection without response'))
[2025-04-29T01:14:15.547+0000] {taskinstance.py:1406} INFO - Marking task as FAILED. dag_id=user_processing, task_id=is_api_available, execution_date=20250428T000000, start_date=20250429T000324, end_date=20250429T011415
[2025-04-29T01:14:15.569+0000] {standard_task_runner.py:105} ERROR - Failed to execute job 286 for task is_api_available (('Connection aborted.', RemoteDisconnected('Remote end closed connection without response')); 4359)
[2025-04-29T01:14:15.611+0000] {local_task_job.py:164} INFO - Task exited with return code 1
[2025-04-29T01:14:15.668+0000] {local_task_job.py:273} INFO - 0 downstream tasks scheduled from follow-on schedule check
