[2025-04-28T10:35:41.026+0000] {taskinstance.py:1165} INFO - Dependencies all met for <TaskInstance: xcom_dag.branch scheduled__2025-04-08T00:00:00+00:00 [queued]>
[2025-04-28T10:35:41.134+0000] {taskinstance.py:1165} INFO - Dependencies all met for <TaskInstance: xcom_dag.branch scheduled__2025-04-08T00:00:00+00:00 [queued]>
[2025-04-28T10:35:41.145+0000] {taskinstance.py:1362} INFO - 
--------------------------------------------------------------------------------
[2025-04-28T10:35:41.148+0000] {taskinstance.py:1363} INFO - Starting attempt 1 of 1
[2025-04-28T10:35:41.150+0000] {taskinstance.py:1364} INFO - 
--------------------------------------------------------------------------------
[2025-04-28T10:35:41.331+0000] {taskinstance.py:1383} INFO - Executing <Task(BranchPythonOperator): branch> on 2025-04-08 00:00:00+00:00
[2025-04-28T10:35:41.371+0000] {standard_task_runner.py:55} INFO - Started process 172 to run task
[2025-04-28T10:35:41.388+0000] {standard_task_runner.py:82} INFO - Running: ['***', 'tasks', 'run', 'xcom_dag', 'branch', 'scheduled__2025-04-08T00:00:00+00:00', '--job-id', '251', '--raw', '--subdir', 'DAGS_FOLDER/xcom_dag.py', '--cfg-path', '/tmp/tmp6xc5gxmr']
[2025-04-28T10:35:41.429+0000] {standard_task_runner.py:83} INFO - Job 251: Subtask branch
[2025-04-28T10:35:42.301+0000] {task_command.py:376} INFO - Running <TaskInstance: xcom_dag.branch scheduled__2025-04-08T00:00:00+00:00 [running]> on host fae2b1eff5d6
[2025-04-28T10:35:43.315+0000] {taskinstance.py:1592} INFO - Exporting the following env vars:
AIRFLOW_CTX_DAG_OWNER=***
AIRFLOW_CTX_DAG_ID=xcom_dag
AIRFLOW_CTX_TASK_ID=branch
AIRFLOW_CTX_EXECUTION_DATE=2025-04-08T00:00:00+00:00
AIRFLOW_CTX_TRY_NUMBER=1
AIRFLOW_CTX_DAG_RUN_ID=scheduled__2025-04-08T00:00:00+00:00
[2025-04-28T10:35:43.324+0000] {taskinstance.py:1851} ERROR - Task failed with exception
Traceback (most recent call last):
  File "/home/airflow/.local/lib/python3.7/site-packages/airflow/operators/python.py", line 211, in execute
    branch = super().execute(context)
  File "/home/airflow/.local/lib/python3.7/site-packages/airflow/operators/python.py", line 175, in execute
    return_value = self.execute_callable()
  File "/home/airflow/.local/lib/python3.7/site-packages/airflow/operators/python.py", line 193, in execute_callable
    return self.python_callable(*self.op_args, **self.op_kwargs)
  File "/opt/airflow/dags/xcom_dag.py", line 14, in _branch
    value = ti.xcom_push(key='my_key', task_ids='t1')
  File "/home/airflow/.local/lib/python3.7/site-packages/airflow/utils/session.py", line 75, in wrapper
    return func(*args, session=session, **kwargs)
TypeError: xcom_push() got an unexpected keyword argument 'task_ids'
[2025-04-28T10:35:43.410+0000] {taskinstance.py:1406} INFO - Marking task as FAILED. dag_id=xcom_dag, task_id=branch, execution_date=20250408T000000, start_date=20250428T103541, end_date=20250428T103543
[2025-04-28T10:35:43.545+0000] {standard_task_runner.py:105} ERROR - Failed to execute job 251 for task branch (xcom_push() got an unexpected keyword argument 'task_ids'; 172)
[2025-04-28T10:35:43.709+0000] {local_task_job.py:164} INFO - Task exited with return code 1
[2025-04-28T10:35:44.412+0000] {local_task_job.py:273} INFO - 0 downstream tasks scheduled from follow-on schedule check
