[2025-04-03T08:43:08.156+0000] {taskinstance.py:1165} INFO - Dependencies all met for <TaskInstance: user_processing.process_user manual__2025-04-03T08:42:59.732271+00:00 [queued]>
[2025-04-03T08:43:08.160+0000] {taskinstance.py:1165} INFO - Dependencies all met for <TaskInstance: user_processing.process_user manual__2025-04-03T08:42:59.732271+00:00 [queued]>
[2025-04-03T08:43:08.161+0000] {taskinstance.py:1362} INFO - 
--------------------------------------------------------------------------------
[2025-04-03T08:43:08.161+0000] {taskinstance.py:1363} INFO - Starting attempt 1 of 1
[2025-04-03T08:43:08.161+0000] {taskinstance.py:1364} INFO - 
--------------------------------------------------------------------------------
[2025-04-03T08:43:08.166+0000] {taskinstance.py:1383} INFO - Executing <Task(PythonOperator): process_user> on 2025-04-03 08:42:59.732271+00:00
[2025-04-03T08:43:08.169+0000] {standard_task_runner.py:55} INFO - Started process 4773 to run task
[2025-04-03T08:43:08.171+0000] {standard_task_runner.py:82} INFO - Running: ['***', 'tasks', 'run', 'user_processing', 'process_user', 'manual__2025-04-03T08:42:59.732271+00:00', '--job-id', '20', '--raw', '--subdir', 'DAGS_FOLDER/user_processing.py', '--cfg-path', '/tmp/tmpr46r0uxx']
[2025-04-03T08:43:08.172+0000] {standard_task_runner.py:83} INFO - Job 20: Subtask process_user
[2025-04-03T08:43:08.207+0000] {task_command.py:376} INFO - Running <TaskInstance: user_processing.process_user manual__2025-04-03T08:42:59.732271+00:00 [running]> on host dd456f953b15
[2025-04-03T08:43:08.247+0000] {taskinstance.py:1592} INFO - Exporting the following env vars:
AIRFLOW_CTX_DAG_OWNER=***
AIRFLOW_CTX_DAG_ID=user_processing
AIRFLOW_CTX_TASK_ID=process_user
AIRFLOW_CTX_EXECUTION_DATE=2025-04-03T08:42:59.732271+00:00
AIRFLOW_CTX_TRY_NUMBER=1
AIRFLOW_CTX_DAG_RUN_ID=manual__2025-04-03T08:42:59.732271+00:00
[2025-04-03T08:43:08.249+0000] {taskinstance.py:1851} ERROR - Task failed with exception
Traceback (most recent call last):
  File "/home/airflow/.local/lib/python3.7/site-packages/airflow/operators/python.py", line 175, in execute
    return_value = self.execute_callable()
  File "/home/airflow/.local/lib/python3.7/site-packages/airflow/operators/python.py", line 193, in execute_callable
    return self.python_callable(*self.op_args, **self.op_kwargs)
  File "/opt/airflow/dags/user_processing.py", line 19, in _process_user
    user = ti.xcom_pull(task_id="extract_user")  # Get user data from XCom
  File "/home/airflow/.local/lib/python3.7/site-packages/airflow/utils/session.py", line 75, in wrapper
    return func(*args, session=session, **kwargs)
TypeError: xcom_pull() got an unexpected keyword argument 'task_id'
[2025-04-03T08:43:08.255+0000] {taskinstance.py:1406} INFO - Marking task as FAILED. dag_id=user_processing, task_id=process_user, execution_date=20250403T084259, start_date=20250403T084308, end_date=20250403T084308
[2025-04-03T08:43:08.260+0000] {standard_task_runner.py:105} ERROR - Failed to execute job 20 for task process_user (xcom_pull() got an unexpected keyword argument 'task_id'; 4773)
[2025-04-03T08:43:08.268+0000] {local_task_job.py:164} INFO - Task exited with return code 1
[2025-04-03T08:43:08.282+0000] {local_task_job.py:273} INFO - 0 downstream tasks scheduled from follow-on schedule check
