[2025-04-28T10:36:37.310+0000] {taskinstance.py:1165} INFO - Dependencies all met for <TaskInstance: user_processing.extract_user scheduled__2025-04-27T00:00:00+00:00 [queued]>
[2025-04-28T10:36:37.319+0000] {taskinstance.py:1165} INFO - Dependencies all met for <TaskInstance: user_processing.extract_user scheduled__2025-04-27T00:00:00+00:00 [queued]>
[2025-04-28T10:36:37.320+0000] {taskinstance.py:1362} INFO - 
--------------------------------------------------------------------------------
[2025-04-28T10:36:37.320+0000] {taskinstance.py:1363} INFO - Starting attempt 1 of 1
[2025-04-28T10:36:37.320+0000] {taskinstance.py:1364} INFO - 
--------------------------------------------------------------------------------
[2025-04-28T10:36:37.330+0000] {taskinstance.py:1383} INFO - Executing <Task(SimpleHttpOperator): extract_user> on 2025-04-27 00:00:00+00:00
[2025-04-28T10:36:37.338+0000] {standard_task_runner.py:55} INFO - Started process 281 to run task
[2025-04-28T10:36:37.343+0000] {standard_task_runner.py:82} INFO - Running: ['***', 'tasks', 'run', 'user_processing', 'extract_user', 'scheduled__2025-04-27T00:00:00+00:00', '--job-id', '272', '--raw', '--subdir', 'DAGS_FOLDER/user_processing.py', '--cfg-path', '/tmp/tmp7bjls1ca']
[2025-04-28T10:36:37.345+0000] {standard_task_runner.py:83} INFO - Job 272: Subtask extract_user
[2025-04-28T10:36:37.393+0000] {task_command.py:376} INFO - Running <TaskInstance: user_processing.extract_user scheduled__2025-04-27T00:00:00+00:00 [running]> on host fae2b1eff5d6
[2025-04-28T10:36:37.443+0000] {taskinstance.py:1592} INFO - Exporting the following env vars:
AIRFLOW_CTX_DAG_OWNER=***
AIRFLOW_CTX_DAG_ID=user_processing
AIRFLOW_CTX_TASK_ID=extract_user
AIRFLOW_CTX_EXECUTION_DATE=2025-04-27T00:00:00+00:00
AIRFLOW_CTX_TRY_NUMBER=1
AIRFLOW_CTX_DAG_RUN_ID=scheduled__2025-04-27T00:00:00+00:00
[2025-04-28T10:36:37.444+0000] {http.py:121} INFO - Calling HTTP method
[2025-04-28T10:36:37.455+0000] {base.py:71} INFO - Using connection ID 'user_api' for task execution.
[2025-04-28T10:36:37.458+0000] {http.py:148} INFO - Sending 'GET' to url: https://randomuser.me/api/
[2025-04-28T10:36:45.618+0000] {http.py:161} ERROR - HTTP error: Bad Gateway
[2025-04-28T10:36:45.620+0000] {http.py:162} ERROR - <html>
<head>
<title>Uh oh, something bad happened</title>
</head>
<body align='center'>
<h1 align='center'>Uh oh, something bad happened</h1>
<a class="twitter-timeline" data-width="450" data-height="700" data-theme="light" href="https://twitter.com/randomapi">Tweets by randomapi</a> <script async src="//platform.twitter.com/widgets.js" charset="utf-8"></script>
</body>
</html>

[2025-04-28T10:36:45.640+0000] {taskinstance.py:1851} ERROR - Task failed with exception
Traceback (most recent call last):
  File "/home/airflow/.local/lib/python3.7/site-packages/airflow/providers/http/hooks/http.py", line 159, in check_response
    response.raise_for_status()
  File "/home/airflow/.local/lib/python3.7/site-packages/requests/models.py", line 1021, in raise_for_status
    raise HTTPError(http_error_msg, response=self)
requests.exceptions.HTTPError: 502 Server Error: Bad Gateway for url: https://randomuser.me/api/

During handling of the above exception, another exception occurred:

Traceback (most recent call last):
  File "/home/airflow/.local/lib/python3.7/site-packages/airflow/providers/http/operators/http.py", line 123, in execute
    response = http.run(self.endpoint, self.data, self.headers, self.extra_options)
  File "/home/airflow/.local/lib/python3.7/site-packages/airflow/providers/http/hooks/http.py", line 149, in run
    return self.run_and_check(session, prepped_request, extra_options)
  File "/home/airflow/.local/lib/python3.7/site-packages/airflow/providers/http/hooks/http.py", line 202, in run_and_check
    self.check_response(response)
  File "/home/airflow/.local/lib/python3.7/site-packages/airflow/providers/http/hooks/http.py", line 163, in check_response
    raise AirflowException(str(response.status_code) + ":" + response.reason)
airflow.exceptions.AirflowException: 502:Bad Gateway
[2025-04-28T10:36:45.649+0000] {taskinstance.py:1406} INFO - Marking task as FAILED. dag_id=user_processing, task_id=extract_user, execution_date=20250427T000000, start_date=20250428T103637, end_date=20250428T103645
[2025-04-28T10:36:45.671+0000] {standard_task_runner.py:105} ERROR - Failed to execute job 272 for task extract_user (502:Bad Gateway; 281)
[2025-04-28T10:36:45.710+0000] {local_task_job.py:164} INFO - Task exited with return code 1
[2025-04-28T10:36:45.742+0000] {local_task_job.py:273} INFO - 0 downstream tasks scheduled from follow-on schedule check
