[2025-04-06T00:00:05.146+0000] {taskinstance.py:1165} INFO - Dependencies all met for <TaskInstance: xcom_dag.branch scheduled__2025-04-05T00:00:00+00:00 [queued]>
[2025-04-06T00:00:05.153+0000] {taskinstance.py:1165} INFO - Dependencies all met for <TaskInstance: xcom_dag.branch scheduled__2025-04-05T00:00:00+00:00 [queued]>
[2025-04-06T00:00:05.153+0000] {taskinstance.py:1362} INFO - 
--------------------------------------------------------------------------------
[2025-04-06T00:00:05.153+0000] {taskinstance.py:1363} INFO - Starting attempt 1 of 1
[2025-04-06T00:00:05.154+0000] {taskinstance.py:1364} INFO - 
--------------------------------------------------------------------------------
[2025-04-06T00:00:05.161+0000] {taskinstance.py:1383} INFO - Executing <Task(BranchPythonOperator): branch> on 2025-04-05 00:00:00+00:00
[2025-04-06T00:00:05.165+0000] {standard_task_runner.py:55} INFO - Started process 2701 to run task
[2025-04-06T00:00:05.169+0000] {standard_task_runner.py:82} INFO - Running: ['***', 'tasks', 'run', 'xcom_dag', 'branch', 'scheduled__2025-04-05T00:00:00+00:00', '--job-id', '109', '--raw', '--subdir', 'DAGS_FOLDER/xcom_dag.py', '--cfg-path', '/tmp/tmpvldjw40z']
[2025-04-06T00:00:05.170+0000] {standard_task_runner.py:83} INFO - Job 109: Subtask branch
[2025-04-06T00:00:05.223+0000] {task_command.py:376} INFO - Running <TaskInstance: xcom_dag.branch scheduled__2025-04-05T00:00:00+00:00 [running]> on host 1dadd347fcc8
[2025-04-06T00:00:05.276+0000] {taskinstance.py:1592} INFO - Exporting the following env vars:
AIRFLOW_CTX_DAG_OWNER=***
AIRFLOW_CTX_DAG_ID=xcom_dag
AIRFLOW_CTX_TASK_ID=branch
AIRFLOW_CTX_EXECUTION_DATE=2025-04-05T00:00:00+00:00
AIRFLOW_CTX_TRY_NUMBER=1
AIRFLOW_CTX_DAG_RUN_ID=scheduled__2025-04-05T00:00:00+00:00
[2025-04-06T00:00:05.277+0000] {taskinstance.py:1851} ERROR - Task failed with exception
Traceback (most recent call last):
  File "/home/airflow/.local/lib/python3.7/site-packages/airflow/operators/python.py", line 211, in execute
    branch = super().execute(context)
  File "/home/airflow/.local/lib/python3.7/site-packages/airflow/operators/python.py", line 175, in execute
    return_value = self.execute_callable()
  File "/home/airflow/.local/lib/python3.7/site-packages/airflow/operators/python.py", line 193, in execute_callable
    return self.python_callable(*self.op_args, **self.op_kwargs)
  File "/opt/airflow/dags/xcom_dag.py", line 14, in _branch
    value = ti.xcom_push(key='my_key', task_ids='t1')
  File "/home/airflow/.local/lib/python3.7/site-packages/airflow/utils/session.py", line 75, in wrapper
    return func(*args, session=session, **kwargs)
TypeError: xcom_push() got an unexpected keyword argument 'task_ids'
[2025-04-06T00:00:05.284+0000] {taskinstance.py:1406} INFO - Marking task as FAILED. dag_id=xcom_dag, task_id=branch, execution_date=20250405T000000, start_date=20250406T000005, end_date=20250406T000005
[2025-04-06T00:00:05.292+0000] {standard_task_runner.py:105} ERROR - Failed to execute job 109 for task branch (xcom_push() got an unexpected keyword argument 'task_ids'; 2701)
[2025-04-06T00:00:05.308+0000] {local_task_job.py:164} INFO - Task exited with return code 1
[2025-04-06T00:00:05.333+0000] {local_task_job.py:273} INFO - 0 downstream tasks scheduled from follow-on schedule check
