[2025-04-28T10:35:40.956+0000] {taskinstance.py:1165} INFO - Dependencies all met for <TaskInstance: user_processing.is_api_available scheduled__2025-04-08T00:00:00+00:00 [queued]>
[2025-04-28T10:35:41.098+0000] {taskinstance.py:1165} INFO - Dependencies all met for <TaskInstance: user_processing.is_api_available scheduled__2025-04-08T00:00:00+00:00 [queued]>
[2025-04-28T10:35:41.111+0000] {taskinstance.py:1362} INFO - 
--------------------------------------------------------------------------------
[2025-04-28T10:35:41.117+0000] {taskinstance.py:1363} INFO - Starting attempt 1 of 1
[2025-04-28T10:35:41.119+0000] {taskinstance.py:1364} INFO - 
--------------------------------------------------------------------------------
[2025-04-28T10:35:41.379+0000] {taskinstance.py:1383} INFO - Executing <Task(HttpSensor): is_api_available> on 2025-04-08 00:00:00+00:00
[2025-04-28T10:35:41.424+0000] {standard_task_runner.py:55} INFO - Started process 173 to run task
[2025-04-28T10:35:41.567+0000] {standard_task_runner.py:82} INFO - Running: ['***', 'tasks', 'run', 'user_processing', 'is_api_available', 'scheduled__2025-04-08T00:00:00+00:00', '--job-id', '250', '--raw', '--subdir', 'DAGS_FOLDER/user_processing.py', '--cfg-path', '/tmp/tmpzxh06t_q']
[2025-04-28T10:35:41.648+0000] {standard_task_runner.py:83} INFO - Job 250: Subtask is_api_available
[2025-04-28T10:35:42.152+0000] {task_command.py:376} INFO - Running <TaskInstance: user_processing.is_api_available scheduled__2025-04-08T00:00:00+00:00 [running]> on host fae2b1eff5d6
[2025-04-28T10:35:42.748+0000] {taskinstance.py:1592} INFO - Exporting the following env vars:
AIRFLOW_CTX_DAG_OWNER=***
AIRFLOW_CTX_DAG_ID=user_processing
AIRFLOW_CTX_TASK_ID=is_api_available
AIRFLOW_CTX_EXECUTION_DATE=2025-04-08T00:00:00+00:00
AIRFLOW_CTX_TRY_NUMBER=1
AIRFLOW_CTX_DAG_RUN_ID=scheduled__2025-04-08T00:00:00+00:00
[2025-04-28T10:35:42.763+0000] {http.py:120} INFO - Poking: api/
[2025-04-28T10:35:42.955+0000] {base.py:71} INFO - Using connection ID 'user_api' for task execution.
[2025-04-28T10:35:43.000+0000] {http.py:148} INFO - Sending 'GET' to url: https://randomuser.me/api/
[2025-04-28T10:35:51.923+0000] {http.py:161} ERROR - HTTP error: Bad Gateway
[2025-04-28T10:35:51.970+0000] {http.py:162} ERROR - <html>
<head>
<title>Uh oh, something bad happened</title>
</head>
<body align='center'>
<h1 align='center'>Uh oh, something bad happened</h1>
<a class="twitter-timeline" data-width="450" data-height="700" data-theme="light" href="https://twitter.com/randomapi">Tweets by randomapi</a> <script async src="//platform.twitter.com/widgets.js" charset="utf-8"></script>
</body>
</html>

[2025-04-28T10:35:52.118+0000] {taskinstance.py:1851} ERROR - Task failed with exception
Traceback (most recent call last):
  File "/home/airflow/.local/lib/python3.7/site-packages/airflow/providers/http/hooks/http.py", line 159, in check_response
    response.raise_for_status()
  File "/home/airflow/.local/lib/python3.7/site-packages/requests/models.py", line 1021, in raise_for_status
    raise HTTPError(http_error_msg, response=self)
requests.exceptions.HTTPError: 502 Server Error: Bad Gateway for url: https://randomuser.me/api/

During handling of the above exception, another exception occurred:

Traceback (most recent call last):
  File "/home/airflow/.local/lib/python3.7/site-packages/airflow/sensors/base.py", line 189, in execute
    poke_return = self.poke(context)
  File "/home/airflow/.local/lib/python3.7/site-packages/airflow/providers/http/sensors/http.py", line 135, in poke
    raise exc
  File "/home/airflow/.local/lib/python3.7/site-packages/airflow/providers/http/sensors/http.py", line 126, in poke
    extra_options=self.extra_options,
  File "/home/airflow/.local/lib/python3.7/site-packages/airflow/providers/http/hooks/http.py", line 149, in run
    return self.run_and_check(session, prepped_request, extra_options)
  File "/home/airflow/.local/lib/python3.7/site-packages/airflow/providers/http/hooks/http.py", line 202, in run_and_check
    self.check_response(response)
  File "/home/airflow/.local/lib/python3.7/site-packages/airflow/providers/http/hooks/http.py", line 163, in check_response
    raise AirflowException(str(response.status_code) + ":" + response.reason)
airflow.exceptions.AirflowException: 502:Bad Gateway
[2025-04-28T10:35:52.177+0000] {taskinstance.py:1406} INFO - Marking task as FAILED. dag_id=user_processing, task_id=is_api_available, execution_date=20250408T000000, start_date=20250428T103540, end_date=20250428T103552
[2025-04-28T10:35:52.297+0000] {standard_task_runner.py:105} ERROR - Failed to execute job 250 for task is_api_available (502:Bad Gateway; 173)
[2025-04-28T10:35:52.385+0000] {local_task_job.py:164} INFO - Task exited with return code 1
[2025-04-28T10:35:52.801+0000] {local_task_job.py:273} INFO - 0 downstream tasks scheduled from follow-on schedule check
