[2025-04-28T10:35:47.074+0000] {taskinstance.py:1165} INFO - Dependencies all met for <TaskInstance: xcom_dag.branch scheduled__2025-04-27T00:00:00+00:00 [queued]>
[2025-04-28T10:35:48.421+0000] {taskinstance.py:1165} INFO - Dependencies all met for <TaskInstance: xcom_dag.branch scheduled__2025-04-27T00:00:00+00:00 [queued]>
[2025-04-28T10:35:48.491+0000] {taskinstance.py:1362} INFO - 
--------------------------------------------------------------------------------
[2025-04-28T10:35:48.499+0000] {taskinstance.py:1363} INFO - Starting attempt 1 of 1
[2025-04-28T10:35:48.505+0000] {taskinstance.py:1364} INFO - 
--------------------------------------------------------------------------------
[2025-04-28T10:35:48.900+0000] {taskinstance.py:1383} INFO - Executing <Task(BranchPythonOperator): branch> on 2025-04-27 00:00:00+00:00
[2025-04-28T10:35:48.923+0000] {standard_task_runner.py:55} INFO - Started process 193 to run task
[2025-04-28T10:35:48.970+0000] {standard_task_runner.py:82} INFO - Running: ['***', 'tasks', 'run', 'xcom_dag', 'branch', 'scheduled__2025-04-27T00:00:00+00:00', '--job-id', '256', '--raw', '--subdir', 'DAGS_FOLDER/xcom_dag.py', '--cfg-path', '/tmp/tmp73uc8xhd']
[2025-04-28T10:35:49.020+0000] {standard_task_runner.py:83} INFO - Job 256: Subtask branch
[2025-04-28T10:35:50.501+0000] {task_command.py:376} INFO - Running <TaskInstance: xcom_dag.branch scheduled__2025-04-27T00:00:00+00:00 [running]> on host fae2b1eff5d6
[2025-04-28T10:35:51.186+0000] {taskinstance.py:1592} INFO - Exporting the following env vars:
AIRFLOW_CTX_DAG_OWNER=***
AIRFLOW_CTX_DAG_ID=xcom_dag
AIRFLOW_CTX_TASK_ID=branch
AIRFLOW_CTX_EXECUTION_DATE=2025-04-27T00:00:00+00:00
AIRFLOW_CTX_TRY_NUMBER=1
AIRFLOW_CTX_DAG_RUN_ID=scheduled__2025-04-27T00:00:00+00:00
[2025-04-28T10:35:51.240+0000] {taskinstance.py:1851} ERROR - Task failed with exception
Traceback (most recent call last):
  File "/home/airflow/.local/lib/python3.7/site-packages/airflow/operators/python.py", line 211, in execute
    branch = super().execute(context)
  File "/home/airflow/.local/lib/python3.7/site-packages/airflow/operators/python.py", line 175, in execute
    return_value = self.execute_callable()
  File "/home/airflow/.local/lib/python3.7/site-packages/airflow/operators/python.py", line 193, in execute_callable
    return self.python_callable(*self.op_args, **self.op_kwargs)
  File "/opt/airflow/dags/xcom_dag.py", line 14, in _branch
    value = ti.xcom_push(key='my_key', task_ids='t1')
  File "/home/airflow/.local/lib/python3.7/site-packages/airflow/utils/session.py", line 75, in wrapper
    return func(*args, session=session, **kwargs)
TypeError: xcom_push() got an unexpected keyword argument 'task_ids'
[2025-04-28T10:35:51.295+0000] {taskinstance.py:1406} INFO - Marking task as FAILED. dag_id=xcom_dag, task_id=branch, execution_date=20250427T000000, start_date=20250428T103547, end_date=20250428T103551
[2025-04-28T10:35:51.378+0000] {standard_task_runner.py:105} ERROR - Failed to execute job 256 for task branch (xcom_push() got an unexpected keyword argument 'task_ids'; 193)
[2025-04-28T10:35:51.506+0000] {local_task_job.py:164} INFO - Task exited with return code 1
[2025-04-28T10:35:51.893+0000] {local_task_job.py:273} INFO - 0 downstream tasks scheduled from follow-on schedule check
